# lecture

## Exceptions

An exception is a value that indicates that sth "exceptional" has happened, Certainly error

程序员必须总是留意程序中可能出现的错误。

处理程序中的错误**没有单一的正确方式**。为提供一些持久性服务而设计的程序，例如 Web 服务器 应该对错误健壮，将它们记录到日志中为之后考虑，而且在尽可能长的时间内继续接受新的请求。另一方面，Python 解释器通过立即终止以及打印错误信息来处理错误，便于程序员在错误发生时处理它。在任何情况下，程序员必须决定程序如何对异常条件做出反应。

产生异常是一种技巧，终止程序正常执行流，发射异常情况产生的信号，并直接返回到用于响应异常情况的程序的封闭部分。Python 解释器每次在检测到语句或表达式错误时抛出异常。用户也可以使用`raise`或`assert`语句来抛出异常。

其中，`assert`在没有得到真值的情况下会抛出raise

**抛出异常。**异常是一个对象实例，它的类直接或间接继承自`BaseException`类。第一章引入的`assert`语句产生`AssertionError`类的异常。通常，异常实例可以使用`raise`语句来抛出。`raise`语句的通用形式在 [Python 文档](http://docs.python.org/py3k/reference/simple_stmts.html#raise)中描述。`raise`的最常见的作用是构造异常实例并抛出它。

```python
>>> raise Exception('An error occurred')
Traceback (most recent call last):
  File "<stdin>", line 1, in <module>
Exception: an error occurred
```

当异常产生时，当前代码块的语句不会继续执行。

除非异常被解决了（下面会描述），解释器会直接返回到“读取-求值-打印”交互式循环中，或者在 Python 以文件参数启动的情况下会完全终止。

此外，解释器会打印**栈回溯**，它是结构化的文本块，描述了执行分支中的一系列嵌套的活动函数，它们是异常产生的位置。

有些时候，可能会有预料到的异常（按照惯例，assert是不愿意发生的事情）

**处理异常。**异常可以使用封闭的`try`语句来处理。`try`语句由多个子句组成，第一个子句以`try`开始，剩下的以`except`开始。

```python
try:
    <try suite>
except <exception class> as <name>:
    <except suite>
...
```

当`try`语句执行时，`<try suite>`总是会立即执行。`except`子句组只在`<try suite>`执行过程中的异常产生时执行。每个`except`子句指定了需要处理的异常的特定类。例如，如果`<exception class>`是`AssertionError`，那么任何继承自`AssertionError`的类实例都会被处理，标识符`<name>`绑定到所产生的异常对象上，但是这个绑定在`<except suite>`之外并不有效。